<?xml version="1.0" encoding="utf-8"?>
<!-- This URDF was automatically created by SolidWorks to URDF Exporter! Originally created by Stephen Brawner (brawner@gmail.com) 
     Commit Version: 1.6.0-1-g15f4949  Build Version: 1.6.7594.29634
     For more information, please see http://wiki.ros.org/sw_urdf_exporter -->
<robot name="hand_controller">
  
  <!-- <joint name="dummy_joint" type="fixed">
    <parent link="dummy_link" />
    <child  link="base_link" />
  </joint> -->

   <link name="dummy_link" />
  <link name="base_link">
    <inertial>
        <origin xyz="0 0 0.01" rpy="0 0 0" />
        <mass value="0.5"/>
         <inertia
            ixx="0.0014545"
            ixy="4.2968E-08"
            ixz="-1.8199E-07"
            iyy="0.001345"
            iyz="-6.243E-06"
            izz="0.002155" />
    </inertial>
    <visual>
      <geometry>
        <cylinder length="0.02" radius="0.08"/>
      </geometry>
    </visual>
  </link>

  <joint name="dummy_joint" type="fixed">
    <parent link="dummy_link" />
    <child  link="base_link" />
    <origin xyz="0.0 0.0 0.0" rpy="0 0 0" />
  </joint>

   <link name="body_link">
    <inertial>
        <origin xyz="0 0 0.05" rpy="0 0 0" />
        <mass value="2.5"/>
         <inertia
            ixx="0.0014545"
            ixy="4.2968E-08"
            ixz="-1.8199E-07"
            iyy="0.001345"
            iyz="-6.243E-06"
            izz="0.002155" />
    </inertial>
    <visual>
      <origin xyz="0 0 0.06" rpy="0 0 0" />
      <geometry>
        <box size="0.15 0.15 0.12"/>
      </geometry> 
    </visual>
    <visual>
      <origin xyz="0 0 0.14" rpy="0 0 0" />
      <geometry>
        <box size="0.08 0.06 0.06"/>
      </geometry>
    </visual>

    <collision>
      <origin xyz="0 0 0.06" rpy="0 0 0" />
      <geometry>
        <box size="0.15 0.15 0.12"/>
      </geometry> 
    </collision>
    <collision>
      <origin xyz="0 0 0.14" rpy="0 0 0" />
      <geometry>
        <box size="0.08 0.06 0.06"/>
      </geometry>
    </collision>
  </link>

  <joint name="base_joint" type="revolute">
    <parent link="base_link" />
    <child  link="body_link" />
    <origin xyz="0 0 0.01" rpy="0 0 0" />
    <axis xyz="0 0 1"/>
    <limit lower="-3.14" upper="3.14" effort="0" velocity="0" />
  </joint>
  
  
  
    <link name="elbow_link">
    <inertial>
        <origin xyz="0.0 0 0.15" rpy="0 0 0" />
        <mass value="0.25"/>
         <inertia
            ixx="0.0014545"
            ixy="4.2968E-08"
            ixz="-1.8199E-07"
            iyy="0.001345"
            iyz="-6.243E-06"
            izz="0.002155" />
    </inertial>
    <visual>
      <origin xyz="0 -0.02 0.15" rpy="0 0 0" />
      <geometry>
        <box size="0.04 0.04 0.3"/>
      </geometry> 
    </visual>

     <collision>
      <origin xyz="0 -0.02 0.15" rpy="0 0 0" />
      <geometry>
        <box size="0.04 0.04 0.3"/>
      </geometry> 
    </collision>
  </link>
  
  <joint name="shoulder_joint1" type="revolute">
    <parent link="body_link" />
    <child  link="elbow_link" />
    <origin xyz="0.0 -0.03 0.15" rpy="0 0 0" />
    <axis xyz="0 1 0"/>
    <limit lower="-3.14" upper="3.14" effort="0" velocity="0" />
  </joint>



   <link name="capstan_link">
    <inertial>
        <origin xyz="0.05 0 0" rpy="0 0 0" />
        <mass value="0.25"/>
         <inertia
            ixx="0.0014545"
            ixy="4.2968E-08"
            ixz="-1.8199E-07"
            iyy="0.001345"
            iyz="-6.243E-06"
            izz="0.002155" />
    </inertial>
    <visual>
      <origin xyz="0.05 0.01 0" rpy="0 0 0" />
      <geometry>
        <box size="0.1 0.02 0.02"/>
      </geometry> 
    </visual>

     <collision>
      <origin xyz="0.05 0.01 0" rpy="0 0 0" />
      <geometry>
        <box size="0.1 0.02 0.02"/>
      </geometry> 
    </collision>
  </link>

  <joint name="shoulder_joint2" type="revolute">
    <parent link="body_link" />
    <child  link="capstan_link" />
    <origin xyz="0.0 0.03 0.15" rpy="0 0 0" />
    <axis xyz="0 1 0"/>
    <limit lower="-3.14" upper="3.14" effort="0" velocity="0" />
  </joint>


  <link name="support_link">
    <inertial>
        <origin xyz="0.0 -0.15 0" rpy="0 0 0" />
        <mass value="0.25"/>
         <inertia
            ixx="0.0014545"
            ixy="4.2968E-08"
            ixz="-1.8199E-07"
            iyy="0.001345"
            iyz="-6.243E-06"
            izz="0.002155" />
    </inertial>
    <visual>
      <origin xyz="0 -0.01 0.15" rpy="0 0 0" />
      <geometry>
        <box size="0.02 0.02 0.3"/>
      </geometry> 
    </visual>

    <collision>
      <origin xyz="0 -0.01 0.15" rpy="0 0 0" />
      <geometry>
        <box size="0.02 0.02 0.3"/>
      </geometry> 
    </collision>
  </link>

  <joint name="support_joint" type="revolute">
    <parent link="capstan_link" />
    <child  link="support_link" />
    <origin xyz="0.1 0 0" rpy="0 0 0" />
    <axis xyz="0 1 0"/>
    <limit lower="-3.14" upper="3.14" effort="0" velocity="0" />
  </joint>


  <link name="forearm_link">
    <inertial>
        <origin xyz="-0.15 0 0" rpy="0 0 0" />
        <mass value="0.25"/>
         <inertia
            ixx="0.0014545"
            ixy="4.2968E-08"
            ixz="-1.8199E-07"
            iyy="0.001345"
            iyz="-6.243E-06"
            izz="0.002155" />
    </inertial>
    <visual>
      <origin xyz="-0.15 0.02 0" rpy="0 0 0" />
      <geometry>
        <box size="0.5 0.04 0.04"/>
      </geometry> 
    </visual>

    <collision>
      <origin xyz="-0.15 -0.02 0" rpy="0 0 0" />
      <geometry>
        <box size="0.5 0.04 0.04"/>
      </geometry> 
    </collision>
  </link>
  
<!--  <joint name="backelbow_joint" type="revolute">-->
<!--    <parent link="support_link" />-->
<!--    <child  link="forearm_link" />-->
<!--    <origin xyz="0 -0.02 0.3" rpy="0 0 0" />-->
<!--    <axis xyz="0 1 0"/>-->
<!--    <limit lower="-3.14" upper="3.14" effort="0" velocity="0" />-->
<!--  </joint> -->

  <joint name="elbow_joint" type="revolute">
    <parent link="elbow_link" />
    <child  link="forearm_link" />
    <origin xyz="0 0 0.3" rpy="0 0 0" />
    <axis xyz="0 1 0"/>
    <limit lower="-3.14" upper="3.14" effort="0" velocity="0" />
  </joint> 

  <link name="forearm_frame_link">
  </link>
  
  <joint name="forearm_joint" type="fixed">
    <parent link="forearm_link" />
    <child  link="forearm_frame_link" />
    <origin xyz="-0.4 0.02 0.02" rpy="0 0 0" />
  </joint>
  
  <link name="forearm_backframe_link">
  </link>
  
  <joint name="forearm_back_joint" type="fixed">
    <parent link="forearm_link" />
    <child  link="forearm_backframe_link" />
    <origin xyz="0.1 0.04 0.0" rpy="0 0 0" />
  </joint>
  
  <link name="support_arm_frame_link">
  </link>
  
  <joint name="support_frame_joint" type="fixed">
    <parent link="support_link" />
    <child  link="support_arm_frame_link" />
    <origin xyz="0.0 -0.02 0.3" rpy="0 0 0" />
  </joint>

  
<!-- ======================= Gimbal links and joints ======================= -->

<!--  <link name="wrist_link1">-->
<!--    <inertial>-->
<!--        <origin xyz="0.075 -0.075 0" rpy="0 0 0" />-->
<!--        <mass value="0.25"/>-->
<!--         <inertia-->
<!--            ixx="0.0014545"-->
<!--            ixy="4.2968E-08"-->
<!--            ixz="-1.8199E-07"-->
<!--            iyy="0.001345"-->
<!--            iyz="-6.243E-06"-->
<!--            izz="0.002155" />-->
<!--    </inertial>-->
<!--    <visual>-->
<!--      <origin xyz="0.075 0 0.01" rpy="0 0 0" />-->
<!--      <geometry>-->
<!--        <box size="0.15 0.02 0.02"/>-->
<!--      </geometry> -->
<!--    </visual>-->
<!--    <visual>-->
<!--      <origin xyz="0.16 0 0.075" rpy="0 0 0" />-->
<!--      <geometry>-->
<!--        <box size="0.02 0.02 0.15"/>-->
<!--      </geometry> -->
<!--    </visual>-->
<!--  </link>-->
<!--  -->
<!--  <joint name="wrist_joint1" type="revolute">-->
<!--    <parent link="forearm_frame_link" />-->
<!--    <child  link="wrist_link1" />-->
<!--    <origin xyz="0 0 0" rpy="0 0 0" />-->
<!--    <axis xyz="0 0 1"/>-->
<!--    <limit lower="-3.14" upper="3.14" effort="0" velocity="0" />-->
<!--  </joint>-->



<!--  <link name="wrist_link2">-->
<!--    <inertial>-->
<!--        <origin xyz="0.06 0.06 0" rpy="0 0 0" />-->
<!--        <mass value="0.25"/>-->
<!--         <inertia-->
<!--            ixx="0.0014545"-->
<!--            ixy="4.2968E-08"-->
<!--            ixz="-1.8199E-07"-->
<!--            iyy="0.001345"-->
<!--            iyz="-6.243E-06"-->
<!--            izz="0.002155" />-->
<!--    </inertial>-->
<!--    <visual>-->
<!--      <origin xyz="0.06 0 0.01" rpy="0 0 0" />-->
<!--      <geometry>-->
<!--        <box size="0.12 0.02 0.02"/>-->
<!--      </geometry> -->
<!--    </visual>-->
<!--    <visual>-->
<!--      <origin xyz="0.12 0 0.06" rpy="0 0 0" />-->
<!--      <geometry>-->
<!--        <box size="0.02 0.02 0.12"/>-->
<!--      </geometry> -->
<!--    </visual>-->
<!--  </link>-->
<!--  -->
<!--  <joint name="wrist_joint2" type="revolute">-->
<!--    <parent link="wrist_link1" />-->
<!--    <child  link="wrist_link2" />-->
<!--    <origin xyz="0.15 0 0.15" rpy="0 1.57 -3.14" />-->
<!--    <axis xyz="0 0 1"/>-->
<!--    <limit lower="-3.14" upper="3.14" effort="0" velocity="0" />-->
<!--  </joint>-->

<!--  <link name="wrist_link3">-->
<!--    <inertial>-->
<!--        <origin xyz="0.04 -0.04 0" rpy="0 0 0" />-->
<!--        <mass value="0.25"/>-->
<!--         <inertia-->
<!--            ixx="0.0014545"-->
<!--            ixy="4.2968E-08"-->
<!--            ixz="-1.8199E-07"-->
<!--            iyy="0.001345"-->
<!--            iyz="-6.243E-06"-->
<!--            izz="0.002155" />-->
<!--    </inertial>-->
<!--    <visual>-->
<!--      <origin xyz="0.04 0 0.01" rpy="0 0 0" />-->
<!--      <geometry>-->
<!--        <box size="0.08 0.02 0.02"/>-->
<!--      </geometry> -->
<!--    </visual>-->
<!--    <visual>-->
<!--      <origin xyz="0.08 0 0.06" rpy="0 0 0" />-->
<!--      <geometry>-->
<!--        <box size="0.02 0.02 0.08"/>-->
<!--      </geometry> -->
<!--    </visual>-->
<!--  </link>-->
<!--  -->
<!--  <joint name="wrist_joint3" type="revolute">-->
<!--    <parent link="wrist_link2" />-->
<!--    <child  link="wrist_link3" />-->
<!--    <origin xyz="0.12 0 0.12" rpy="0 1.57 -3.14" />-->
<!--    <axis xyz="0 0 1"/>-->
<!--    <limit lower="-3.14" upper="3.14" effort="0" velocity="0" />-->
<!--  </joint>-->

<!--  <link name="gripper_link">-->
<!--  </link>-->
<!--  -->
<!--  <joint name="gripper_joint" type="fixed">-->
<!--    <parent link="wrist_link3" />-->
<!--    <child  link="gripper_link" />-->
<!--    <origin xyz="0.08 0 0.08" rpy="0 -1.57 -3.14" />-->
<!--  </joint>-->



</robot>
